<?xml version='1.0'?>

<robot name="myrobot" xmlns:xacro="http://www.ros.org/wiki/xacro">

  <xacro:property name="cameraSize" value="0.006"/>
  <xacro:property name="cameraMass" value="0.01"/>

  <xacro:include filename="$(find mybot_description)/urdf/mybot.gazebo" />
  <xacro:include filename="$(find mybot_description)/urdf/materials.xacro" />
  <xacro:include filename="$(find mybot_description)/urdf/macros.xacro" />

   <xacro:macro name="box_inertia" params="m x y z">
        <inertial>
		<origin xyz="0.0 0.0 0.1" rpy=" 0 0 0"/>
                <mass value="${m}" />
                <inertia  ixx="${m*(y*y+z*z)/12}" ixy = "0" ixz = "0"
      			  iyy="${m*(x*x+z*z)/12}" iyz = "0"
     			  izz="${m*(x*x+z*z)/12}"/>
        </inertial>
   </xacro:macro>

   <xacro:macro name="cylinder_inertia" params="m r h">
        <inertial>
		<origin xyz="0 0 0" rpy="0 1.5707 1.5707"/>
                <mass value="${m}" />
                <inertia  ixx="${m*(3*r*r+h*h)/12}" ixy = "0" ixz = "0"
    			  iyy="${m*(3*r*r+h*h)/12}" iyz = "0"
    			  izz="${m*r*r/2}"/>
        </inertial>
   </xacro:macro>

   <xacro:macro name="sphere_inertia" params="m x y z">
        <inertial>
                <mass value="${m}" />
                <inertia  ixx="${2*m*r*r/5}" ixy = "0" ixz = "0"
   			  iyy="${2*m*r*r/5}" iyz = "0"
     			  izz="${2*m*r*r/5}"/>
        </inertial>
   </xacro:macro>

<!--XXXXXXXXXXXXXXXXXXXXXXXXXXXXXXXXXXXXXXXXXXXXXXXXXXXXXXXXXXXXXXXXXXXXXXXXXXXXXXXXXXXXXXXXXXX-->

  <link name="chassis">
        <pose>0 0 0.2 0 0 0</pose>

     	<xacro:box_inertia m="1.0" x="0.1" y="0.05" z="0.02"/>

        <visual name="chassis_visual">
            <origin xyz="0.0 0.0 0.0" rpy="0.0 0.0 0.0"/>
            <geometry>
                <box size="0.08 0.049 0.02"/>
            </geometry>
            <material name="white"/>
        </visual>

        <collision name='collision'>
            <geometry>
                <box size="0.08 0.049 0.02"/>
            </geometry>
        </collision>

    </link>

    <link name="left_front_wheel">

        <collision name="collision">
            <origin xyz="0 0 0" rpy="0 1.5707 1.5707"/>
            <geometry>
                <cylinder radius="0.015" length="0.01"/>
            </geometry>    
        </collision>

        <visual name="left_front_wheel_visual">
            <origin xyz="0 0 0" rpy="0 1.5707 1.5707"/>
            <geometry>
                <cylinder radius="0.015" length="0.01"/>
            </geometry>   
        </visual>

        <xacro:cylinder_inertia m="0.2" r="0.015" h="0.01"/>
    </link>

    <link name="left_back_wheel">

        <collision name="collision">
            <origin xyz="0 0 0" rpy="0 1.5707 1.5707"/>
            <geometry>
                <cylinder radius="0.015" length="0.01"/>
            </geometry>    
        </collision>

        <visual name="left_back_wheel_visual">
            <origin xyz="0 0 0" rpy="0 1.5707 1.5707"/>
            <geometry>
                <cylinder radius="0.015" length="0.01"/>
            </geometry>   
        </visual>

        <xacro:cylinder_inertia m="0.2" r="0.015" h="0.01"/>
    </link>

    <link name="right_front_wheel">

        <collision name="collision">
            <origin xyz="0 0 0" rpy="0 1.5707 1.5707"/>
            <geometry>
                <cylinder radius="0.015" length="0.01"/>
            </geometry>    
        </collision>

        <visual name="right_front_wheel_visual">
            <origin xyz="0 0 0" rpy="0 1.5707 1.5707"/>
            <geometry>
                <cylinder radius="0.015" length="0.01"/>
            </geometry>   
        </visual>

        <xacro:cylinder_inertia m="0.2" r="0.015" h="0.01"/>
    </link>

    <link name="right_back_wheel">

        <collision name="collision">
            <origin xyz="0 0 0" rpy="0 1.5707 1.5707"/>
            <geometry>
                <cylinder radius="0.015" length="0.01"/>
            </geometry>    
        </collision>

        <visual name="right_back_wheel_visual">
            <origin xyz="0 0 0" rpy="0 1.5707 1.5707"/>
            <geometry>
                <cylinder radius="0.015" length="0.01"/>
            </geometry>   
        </visual>

        <xacro:cylinder_inertia m="0.2" r="0.015" h="0.01"/>
    </link>

    <joint type="continuous" name="left_front_wheel_joint">
        <origin xyz="0.02 0.03 0.0" rpy="0 0 0"/>
        <child link="left_front_wheel"/>
        <parent link="chassis"/>
        <axis xyz="0 1 0" rpy="0 0 0"/>
        <limit effort="100" velocity="100"/>
        <joint_properties damping="1.0" friction="0.0"/>
    </joint>

    <joint type="continuous" name="left_back_wheel_joint">
        <origin xyz="-0.02 0.03 0.0" rpy="0 0 0"/>
        <child link="left_back_wheel"/>
        <parent link="chassis"/>
        <axis xyz="0 1 0" rpy="0 0 0"/>
        <limit effort="100" velocity="100"/>
        <joint_properties damping="1.0" friction="0.0"/>
    </joint>

    <joint type="continuous" name="right_front_wheel_joint">
        <origin xyz="0.02 -0.03 0.0" rpy="0 0 0"/>
        <child link="right_front_wheel"/>
        <parent link="chassis"/>
        <axis xyz="0 1 0" rpy="0 0 0"/>
        <limit effort="100" velocity="100"/>
        <joint_properties damping="1.0" friction="0.0"/>
    </joint>

    <joint type="continuous" name="right_back_wheel_joint">
        <origin xyz="-0.02 -0.03 0.0" rpy="0 0 0"/>
        <child link="right_back_wheel"/>
        <parent link="chassis"/>
        <axis xyz="0 1 0" rpy="0 0 0"/>
        <limit effort="100" velocity="100"/>
        <joint_properties damping="1.0" friction="0.0"/>
    </joint>



  <link name="camera">
    <collision>
      <origin xyz="0 0 0" rpy="0 0 0"/>
      <geometry>
        <box size="${cameraSize} ${cameraSize} ${cameraSize}"/>
      </geometry>
    </collision>

    <visual>
      <origin xyz="0 0 0" rpy="0 0 0"/>
      <geometry>
        <box size="${cameraSize} ${cameraSize} ${cameraSize}"/>
      </geometry>
      <material name="green"/>
    </visual>

    <inertial>
      <mass value="${cameraMass}" />
      <origin xyz="0 0 0" rpy="0 0 0"/>
      <box_inertia m="${cameraMass}" x="${cameraSize}" y="${cameraSize}" z="${cameraSize}" />
      <inertia ixx="0.1" ixy="0" ixz="0" iyy="0.1" iyz="0" izz="0.1" />
    </inertial>
  </link>

  <joint name="camera_joint" type="fixed">
    <axis xyz="0 1 0" />
    <origin xyz="0 0.0215 0.013" rpy="0 0 1.570796"/>
    <parent link="chassis"/>
    <child link="camera"/>
  </joint>


  <joint name="hokuyo_joint" type="fixed">
    <axis xyz="0 1 0" />
    <origin xyz="0 0 0.02" rpy="0 0 0"/>
    <parent link="chassis"/>
    <child link="hokuyo"/>
  </joint>

  <!-- Hokuyo Laser -->
  <link name="hokuyo">
    <collision>
      <origin xyz="0 0 0" rpy="0 0 0"/>
      <geometry>
    <box size="0.01 0.01 0.02"/>
      </geometry>
    </collision>

    <visual>
      <origin xyz="0 0 0" rpy="0 0 0"/>
      <geometry>
        <mesh filename="package://mybot_description/meshes/hokuyo.dae" scale="0.3 0.3 0.3"/>
      </geometry>
    </visual>

    <inertial>
      <mass value="0.05" />
      <origin xyz="0 0 0" rpy="0 0 0"/>
      <inertia ixx="0.1" ixy="0" ixz="0" iyy="0.1" iyz="0" izz="0.1" />
    </inertial>
  </link>

  <!--transmission name="tran1">
    <type>transmission_interface/SimpleTransmission</type>
    <joint name="left_front_wheel_joint">
      <hardwareInterface>EffortJointInterface</hardwareInterface>
    </joint>
    <actuator name="motor1">
      <hardwareInterface>EffortJointInterface</hardwareInterface>
      <mechanicalReduction>1</mechanicalReduction>
    </actuator>
  </transmission>

  <transmission name="tran2">
    <type>transmission_interface/SimpleTransmission</type>
    <joint name="right_front_wheel_joint">
      <hardwareInterface>EffortJointInterface</hardwareInterface>
    </joint>
    <actuator name="motor2">
      <hardwareInterface>EffortJointInterface</hardwareInterface>
      <mechanicalReduction>1</mechanicalReduction>
    </actuator>
  </transmission>

  <transmission name="tran3">
    <type>transmission_interface/SimpleTransmission</type>
    <joint name="left_back_wheel_joint">
      <hardwareInterface>EffortJointInterface</hardwareInterface>
    </joint>
    <actuator name="motor3">
      <hardwareInterface>EffortJointInterface</hardwareInterface>
      <mechanicalReduction>1</mechanicalReduction>
    </actuator>
  </transmission>

  <transmission name="tran4">
    <type>transmission_interface/SimpleTransmission</type>
    <joint name="right_back_wheel_joint">
      <hardwareInterface>EffortJointInterface</hardwareInterface>
    </joint>
    <actuator name="motor4">
      <hardwareInterface>EffortJointInterface</hardwareInterface>
      <mechanicalReduction>1</mechanicalReduction>
    </actuator>
  </transmission-->



</robot>

